[2024-03-17T09:36:44.580+0500] {taskinstance.py:1979} INFO - Dependencies all met for dep_context=non-requeueable deps ti=<TaskInstance: download_rocket_launches.download_launches manual__2024-03-17T04:36:38.277411+00:00 [queued]>
[2024-03-17T09:36:44.592+0500] {taskinstance.py:1979} INFO - Dependencies all met for dep_context=requeueable deps ti=<TaskInstance: download_rocket_launches.download_launches manual__2024-03-17T04:36:38.277411+00:00 [queued]>
[2024-03-17T09:36:44.593+0500] {taskinstance.py:2193} INFO - Starting attempt 1 of 1
[2024-03-17T09:36:44.739+0500] {taskinstance.py:2217} INFO - Executing <Task(PythonOperator): download_launches> on 2024-03-17 04:36:38.277411+00:00
[2024-03-17T09:36:44.742+0500] {standard_task_runner.py:60} INFO - Started process 13848 to run task
[2024-03-17T09:36:44.745+0500] {standard_task_runner.py:87} INFO - Running: ['airflow', 'tasks', 'run', 'download_rocket_launches', 'download_launches', 'manual__2024-03-17T04:36:38.277411+00:00', '--job-id', '10', '--raw', '--subdir', 'DAGS_FOLDER/download_rocket_launches.py', '--cfg-path', '/tmp/tmpoiqgerrz']
[2024-03-17T09:36:44.746+0500] {standard_task_runner.py:88} INFO - Job 10: Subtask download_launches
[2024-03-17T09:36:44.907+0500] {task_command.py:423} INFO - Running <TaskInstance: download_rocket_launches.download_launches manual__2024-03-17T04:36:38.277411+00:00 [running]> on host muhammadsami-Latitude-E6540
[2024-03-17T09:36:45.175+0500] {taskinstance.py:2513} INFO - Exporting env vars: AIRFLOW_CTX_DAG_OWNER='airflow' AIRFLOW_CTX_DAG_ID='download_rocket_launches' AIRFLOW_CTX_TASK_ID='download_launches' AIRFLOW_CTX_EXECUTION_DATE='2024-03-17T04:36:38.277411+00:00' AIRFLOW_CTX_TRY_NUMBER='1' AIRFLOW_CTX_DAG_RUN_ID='manual__2024-03-17T04:36:38.277411+00:00'
[2024-03-17T09:36:45.176+0500] {taskinstance.py:2731} ERROR - Task failed with exception
Traceback (most recent call last):
  File "/usr/lib/python3.8/pathlib.py", line 1288, in mkdir
    self._accessor.mkdir(self, mode)
FileNotFoundError: [Errno 2] No such file or directory: '/GettingStarted/dags/data'

During handling of the above exception, another exception occurred:

Traceback (most recent call last):
  File "/usr/lib/python3.8/pathlib.py", line 1288, in mkdir
    self._accessor.mkdir(self, mode)
FileNotFoundError: [Errno 2] No such file or directory: '/GettingStarted/dags'

During handling of the above exception, another exception occurred:

Traceback (most recent call last):
  File "/home/muhammadsami/Public/Projects/Airflow/DataPipelineswithApacheAirflow/.env/lib/python3.8/site-packages/airflow/models/taskinstance.py", line 444, in _execute_task
    result = _execute_callable(context=context, **execute_callable_kwargs)
  File "/home/muhammadsami/Public/Projects/Airflow/DataPipelineswithApacheAirflow/.env/lib/python3.8/site-packages/airflow/models/taskinstance.py", line 414, in _execute_callable
    return execute_callable(context=context, **execute_callable_kwargs)
  File "/home/muhammadsami/Public/Projects/Airflow/DataPipelineswithApacheAirflow/.env/lib/python3.8/site-packages/airflow/operators/python.py", line 200, in execute
    return_value = self.execute_callable()
  File "/home/muhammadsami/Public/Projects/Airflow/DataPipelineswithApacheAirflow/.env/lib/python3.8/site-packages/airflow/operators/python.py", line 217, in execute_callable
    return self.python_callable(*self.op_args, **self.op_kwargs)
  File "/home/muhammadsami/Public/Projects/Airflow/DataPipelineswithApacheAirflow/GettingStarted/dags/download_rocket_launches.py", line 26, in _download_launches
    pathlib.Path(
  File "/usr/lib/python3.8/pathlib.py", line 1292, in mkdir
    self.parent.mkdir(parents=True, exist_ok=True)
  File "/usr/lib/python3.8/pathlib.py", line 1292, in mkdir
    self.parent.mkdir(parents=True, exist_ok=True)
  File "/usr/lib/python3.8/pathlib.py", line 1288, in mkdir
    self._accessor.mkdir(self, mode)
PermissionError: [Errno 13] Permission denied: '/GettingStarted'
[2024-03-17T09:36:45.180+0500] {taskinstance.py:1149} INFO - Marking task as FAILED. dag_id=download_rocket_launches, task_id=download_launches, execution_date=20240317T043638, start_date=20240317T043644, end_date=20240317T043645
[2024-03-17T09:36:45.318+0500] {standard_task_runner.py:107} ERROR - Failed to execute job 10 for task download_launches ([Errno 13] Permission denied: '/GettingStarted'; 13848)
[2024-03-17T09:36:45.361+0500] {local_task_job_runner.py:234} INFO - Task exited with return code 1
[2024-03-17T09:36:45.381+0500] {taskinstance.py:3312} INFO - 0 downstream tasks scheduled from follow-on schedule check
